Workbook

Sheet Tabuľka
C2: Záložné vozidlá - pracovný deň | I2: Záložné vozidlá - VÍKEND
B4: osobné číslo | C4: meno | D4: telefónne číslo | E4: miesto | F4: vozidlo | H4: osobné číslo | I4: meno | J4: telefónne číslo | K4: miesto | L4: vozidlo
B5: A - BUS | H5: A - BUS
B6: 6341 | C6: =IFERROR(VLOOKUP(B6, 'Telefónny zoznam'!C1:E2990,2, FALSE), "Name not found") -> Pykal Dušan | D6: =IFERROR(VLOOKUP(B6,'Telefónny zoznam'!C:E, 3, FALSE), "") -> 0908 143 242 | E6: (ZV/22) Depo Hroboňova | F6: 2536 | H6: 15012 | I6: =IFERROR(VLOOKUP(H6, 'Telefónny zoznam'!C3:E2990,2, FALSE), "Name not found") -> Shepel Igor | J6: =IFERROR(VLOOKUP(H6,'Telefónny zoznam'!C:E, 3, FALSE), "") -> 0951 185 892 | K6: (ZV/22) Depo Hroboňova | L6: 2536
B7: 9076 | C7: =IFERROR(VLOOKUP(B7, 'Telefónny zoznam'!C1:E2990,2, FALSE), "Name not found") -> Petrikovič Pavol | D7: =IFERROR(VLOOKUP(B7,'Telefónny zoznam'!C:E, 3, FALSE), "") -> 0907 698 554 | E7: (ZV/31) Pri kríži | F7: 4248 | H7: 9715 | I7: =IFERROR(VLOOKUP(H7, 'Telefónny zoznam'!C3:E2990,2, FALSE), "Name not found") -> Škodler Radovan | J7: =IFERROR(VLOOKUP(H7,'Telefónny zoznam'!C:E, 3, FALSE), "") -> 0915 802 730 | K7: (ZV/31) Pri kríži | L7: 4272
B8: 2815 | C8: =IFERROR(VLOOKUP(B8, 'Telefónny zoznam'!C1:E2990,2, FALSE), "Name not found") -> Haris Peter | D8: =IFERROR(VLOOKUP(B8,'Telefónny zoznam'!C:E, 3, FALSE), "") -> 0905 630 673 | E8: (ZV/33) Kútiky | F8: 2534 | I8: =IFERROR(VLOOKUP(H8, 'Telefónny zoznam'!C3:E2990,2, FALSE), "Name not found") -> Name not found | J8: =IFERROR(VLOOKUP(H8,'Telefónny zoznam'!C:E, 3, FALSE), "")
B9: 17973 | C9: =IFERROR(VLOOKUP(B9, 'Telefónny zoznam'!C1:E2990,2, FALSE), "Name not found") -> Lavrenov Dmytro | D9: =IFERROR(VLOOKUP(B9,'Telefónny zoznam'!C:E, 3, FALSE), "") -> 0951 524 526 | E9: (ZV/23) Most SNP | F9: 3327 | H9: 9586 | I9: =IFERROR(VLOOKUP(H9, 'Telefónny zoznam'!C3:E2990,2, FALSE), "Name not found") -> Matúšek Peter KPČ | J9: =IFERROR(VLOOKUP(H9,'Telefónny zoznam'!C:E, 3, FALSE), "") -> 0948 231 490 | K9: (ZV/23) Most SNP | L9: 3328
B10: 15610 | C10: =IFERROR(VLOOKUP(B10, 'Telefónny zoznam'!C1:E2990,2, FALSE), "Name not found") -> Lehuta Vladimír | D10: =IFERROR(VLOOKUP(B10,'Telefónny zoznam'!C:E, 3, FALSE), "") -> 0918 660 526 | E10: (ZV/21) Cintorín Vrakuňa | F10: 3315 | H10: 15167 | I10: =IFERROR(VLOOKUP(H10, 'Telefónny zoznam'!C3:E2990,2, FALSE), "Name not found") -> Grossman Peter | J10: =IFERROR(VLOOKUP(H10,'Telefónny zoznam'!C:E, 3, FALSE), "") -> 0903 476 105 | K10: (ZV/21) Cintorín Vrakuňa | L10: 3315
B11: 7926 | C11: =IFERROR(VLOOKUP(B11, 'Telefónny zoznam'!C1:E2990,2, FALSE), "Name not found") -> Kováč Peter | D11: =IFERROR(VLOOKUP(B11,'Telefónny zoznam'!C:E, 3, FALSE), "") -> 0903 379 899 | E11: (ZV/14) Nové SND | F11: 1051 | I11: =IFERROR(VLOOKUP(H11, 'Telefónny zoznam'!C3:E2990,2, FALSE), "Name not found") -> Name not found | J11: =IFERROR(VLOOKUP(H11,'Telefónny zoznam'!C:E, 3, FALSE), "")
B12: 4646 | C12: =IFERROR(VLOOKUP(B12, 'Telefónny zoznam'!C1:E2990,2, FALSE), "Name not found") -> Kušnír Roman | D12: =IFERROR(VLOOKUP(B12,'Telefónny zoznam'!C:E, 3, FALSE), "") -> 0910 691 713 | E12: (ZV/24) Ovsište | F12: 3328 | H12: 12561 | I12: =IFERROR(VLOOKUP(H12, 'Telefónny zoznam'!C3:E2990,2, FALSE), "Name not found") -> Hýlek Peter (KPČ) | J12: =IFERROR(VLOOKUP(H12,'Telefónny zoznam'!C:E, 3, FALSE), "") -> 0915 761 570 | K12: (ZV/33) Ovsište | L12: 2213
B13: 11076 | C13: =IFERROR(VLOOKUP(B13, 'Telefónny zoznam'!C3:E2990,2, FALSE), "Name not found") -> Szabo Jozef I. | D13: =IFERROR(VLOOKUP(B13,'Telefónny zoznam'!C:E, 3, FALSE), "") -> 0949 765 354 | E13: (ZV/13) Súhvezdná | F13: 1862 | H13: 10764 | I13: =IFERROR(VLOOKUP(H13, 'Telefónny zoznam'!C3:E2990,2, FALSE), "Name not found") -> Okatý Jaroslav | J13: =IFERROR(VLOOKUP(H13,'Telefónny zoznam'!C:E, 3, FALSE), "") -> 0944 319 048 | K13: (ZV/13) Súhvezdná | L13: 2250
B14: 242 | C14: =IFERROR(VLOOKUP(B14, 'Telefónny zoznam'!C3:E2990,2, FALSE), "Name not found") -> Pajdlhauser Miroslav | D14: =IFERROR(VLOOKUP(B14,'Telefónny zoznam'!C:E, 3, FALSE), "") -> 0915 375 128 | E14: (ZV/15) Čiližská | F14: 2250 | I14: =IFERROR(VLOOKUP(H14, 'Telefónny zoznam'!C3:E300,2, FALSE), "Name not found") -> Name not found | J14: =IFERROR(VLOOKUP(H14,'Telefónny zoznam'!C:E, 3, FALSE), "")
B15: 13624 | C15: =IFERROR(VLOOKUP(B15, 'Telefónny zoznam'!C3:E2990,2, FALSE), "Name not found") -> Lomjanszki Adam | D15: =IFERROR(VLOOKUP(B15,'Telefónny zoznam'!C:E, 3, FALSE), "") -> 0949 883 002 | E15: (ZV/11) Depo Krasňany | F15: 2409 | H15: 8758 | I15: =IFERROR(VLOOKUP(H15, 'Telefónny zoznam'!C3:E2990,2, FALSE), "Name not found") -> Karcel Richard | J15: =IFERROR(VLOOKUP(H15,'Telefónny zoznam'!C:E, 3, FALSE), "") -> 0902 334 951 | K15: (ZV/11) Depo Krasňany | L15: 2409
B16: 11131 | C16: =IFERROR(VLOOKUP(B16, 'Telefónny zoznam'!C3:E2990,2, FALSE), "Name not found") -> Karas Ľubomír | D16: =IFERROR(VLOOKUP(B16,'Telefónny zoznam'!C:E, 3, FALSE), "") -> 0903 775 686 | E16: (ZV/12) Depo Trnávka | F16: 2563 | H16: 12032 | I16: =IFERROR(VLOOKUP(H16, 'Telefónny zoznam'!C3:E2990,2, FALSE), "Name not found") -> Martinovič Pavol | J16: =IFERROR(VLOOKUP(H16,'Telefónny zoznam'!C:E, 3, FALSE), "") -> 0902 175 061 | K16: (ZV/12) Depo Trnávka | L16: 2563
B17: 5965 | C17: =IFERROR(VLOOKUP(B17, 'Telefónny zoznam'!C3:E2990,2, FALSE), "Name not found") -> Jankovič Vladimír | D17: =IFERROR(VLOOKUP(B17,'Telefónny zoznam'!C:E, 3, FALSE), "") -> 0918 889 959 | E17: (ZV/32) Depo Petržalka | F17: 4274 | H17: 16015 | I17: =IFERROR(VLOOKUP(H17, 'Telefónny zoznam'!C3:E2990,2, FALSE), "Name not found") -> Kolárik Lukáš | J17: =IFERROR(VLOOKUP(H17,'Telefónny zoznam'!C:E, 3, FALSE), "") -> 0949 195 282 | K17: (ZV/32) Depo Petržalka | L17: 4274
B18: 11136 | C18: =IFERROR(VLOOKUP(B18, 'Telefónny zoznam'!C3:E2990,2, FALSE), "Name not found") -> Jakubek Stanislav (KPČ) | D18: =IFERROR(VLOOKUP(B18,'Telefónny zoznam'!C:E, 3, FALSE), "") -> 0905 404 283 | E18: (ZV/25) Letisko CD | F18: 3223 | H18: 1162 | I18: =IFERROR(VLOOKUP(H18, 'Telefónny zoznam'!C3:E2990,2, FALSE), "Name not found") -> Král Ivan | J18: =IFERROR(VLOOKUP(H18,'Telefónny zoznam'!C:E, 3, FALSE), "") -> 0902 326 892 | K18: (ZV/25) Letisko CD | L18: 3222
B19: 14512 | C19: =IFERROR(VLOOKUP(B19, 'Telefónny zoznam'!C3:E2990,2, FALSE), "Name not found") -> Oliinyk Andrii | D19: =IFERROR(VLOOKUP(B19,'Telefónny zoznam'!C:E, 3, FALSE), "") -> 0950 271 026 | E19: (ZV/26) Letisko | F19: 3227 | H19: 15392 | I19: =IFERROR(VLOOKUP(H19, 'Telefónny zoznam'!C3:E2990,2, FALSE), "Name not found") -> Maršovský Dárius | J19: =IFERROR(VLOOKUP(H19,'Telefónny zoznam'!C:E, 3, FALSE), "") -> 0944 076 031 | K19: (ZV/26) Letisko | L19: 3221
C20: =IFERROR(VLOOKUP(B20, 'Telefónny zoznam'!C3:E2990,2, FALSE), "Name not found") -> Name not found | D20: =IFERROR(VLOOKUP(B20,'Telefónny zoznam'!C:E, 3, FALSE), "") | I20: =IFERROR(VLOOKUP(H20, 'Telefónny zoznam'!C3:E2990,2, FALSE), "Name not found") -> Name not found | J20: =IFERROR(VLOOKUP(H20,'Telefónny zoznam'!C:E, 3, FALSE), "")
D21: =IFERROR(VLOOKUP(B21,'Telefónny zoznam'!C:E, 3, FALSE), "") | J21: =IFERROR(VLOOKUP(H21,'Telefónny zoznam'!C:E, 3, FALSE), "")
B22: E - BUS | H22: E - BUS
B23: 16525 | C23: =IFERROR(VLOOKUP(B23, 'Telefónny zoznam'!C3:E2990,2, FALSE), "Name not found") -> Vašek Dušan | D23: =IFERROR(VLOOKUP(B23,'Telefónny zoznam'!C:E, 3, FALSE), "") -> 0904 366 736 | E23: (ZV/1) Južné mesto | F23: 7504 | H23: 16365 | I23: =IFERROR(VLOOKUP(H23, 'Telefónny zoznam'!C3:E2990,2, FALSE), "Name not found") -> Kulík Martin | J23: =IFERROR(VLOOKUP(H23,'Telefónny zoznam'!C:E, 3, FALSE), "") -> 0944 400 784 | K23: (ZV/1) Južné mesto | L23: 7507
B24: 18199 | C24: =IFERROR(VLOOKUP(B24, 'Telefónny zoznam'!C3:E2990,2, FALSE), "Name not found") -> Tollár Michal | D24: =IFERROR(VLOOKUP(B24,'Telefónny zoznam'!C:E, 3, FALSE), "") -> 0914 119 623 | E24: (ZV/2) Astronomická | F24: 7501 | I24: =IFERROR(VLOOKUP(H24, 'Telefónny zoznam'!C3:E2990,2, FALSE), "Name not found") -> Name not found | J24: =IFERROR(VLOOKUP(H24,'Telefónny zoznam'!C:E, 3, FALSE), "")
B25: 13965 | C25: =IFERROR(VLOOKUP(B25, 'Telefónny zoznam'!C3:E2990,2, FALSE), "Name not found") -> Žifčák Mário | D25: =IFERROR(VLOOKUP(B25,'Telefónny zoznam'!C:E, 3, FALSE), "") -> 0911 351 231 | E25: (ZV/3) Stn. Nové Mesto | F25: 7412 | I25: =IFERROR(VLOOKUP(H25, 'Telefónny zoznam'!C3:E2990,2, FALSE), "Name not found") -> Name not found | J25: =IFERROR(VLOOKUP(H25,'Telefónny zoznam'!C:E, 3, FALSE), "")
B26: 18353 | C26: =IFERROR(VLOOKUP(B26, 'Telefónny zoznam'!C3:E2990,2, FALSE), "Name not found") -> Tibenský Tibor | D26: =IFERROR(VLOOKUP(B26,'Telefónny zoznam'!C:E, 3, FALSE), "") -> 0903 718 222 | E26: (ZV/4) Komisárky | F26: 7526 | H26: 14694 | I26: =IFERROR(VLOOKUP(H26, 'Telefónny zoznam'!C3:E2990,2, FALSE), "Name not found") -> Ščasný Lukáš | J26: =IFERROR(VLOOKUP(H26,'Telefónny zoznam'!C:E, 3, FALSE), "") -> 0950 896 217 | K26: (ZV/4) Komisárky | L26: 7504
B27: 17889 | C27: =IFERROR(VLOOKUP(B27, 'Telefónny zoznam'!C3:E2990,2, FALSE), "Name not found") -> Kozlík Štefan | D27: =IFERROR(VLOOKUP(B27,'Telefónny zoznam'!C:E, 3, FALSE), "") -> 0911 081 508 | E27: (ZV/5) Pri kríži | F27: 7402 | H27: 18060 | I27: =IFERROR(VLOOKUP(H27, 'Telefónny zoznam'!C3:E2990,2, FALSE), "Name not found") -> Hluško Jakub KPČ | J27: =IFERROR(VLOOKUP(H27,'Telefónny zoznam'!C:E, 3, FALSE), "") -> 0918 421 460 | K27: (ZV/5) Pri kríži | L27: 7409
D28: =IFERROR(VLOOKUP(B28,'Telefónny zoznam'!C:E, 3, FALSE), "") | H28: 7291 | I28: =IFERROR(VLOOKUP(H28, 'Telefónny zoznam'!C3:E2990,2, FALSE), "Name not found") -> Janček Vladimír | J28: =IFERROR(VLOOKUP(H28,'Telefónny zoznam'!C:E, 3, FALSE), "") -> 0905 332 469 | K28: (ZV/6) Hlavná stanica | L28: 7509
B29: T - BUS | H29: T - BUS
B30: 13816 | C30: =IFERROR(VLOOKUP(B30, 'Telefónny zoznam'!C3:E2990,2, FALSE), "Name not found") -> Hojzák Matúš | D30: =IFERROR(VLOOKUP(B30,'Telefónny zoznam'!C:E, 3, FALSE), "") -> 0903 222 232 | E30: Depo Hroboňova | F30: 6131 | H30: 13812 | I30: =IFERROR(VLOOKUP(H30, 'Telefónny zoznam'!C3:E2990,2, FALSE), "Name not found") -> Lecsö Tibor | J30: =IFERROR(VLOOKUP(H30,'Telefónny zoznam'!C:E, 3, FALSE), "") -> 0949 492 443 | K30: Depo Hroboňova | L30: 6128
B31: 18446 | C31: =IFERROR(VLOOKUP(B31, 'Telefónny zoznam'!C3:E2990,2, FALSE), "Name not found") -> Minárik Dominik (KPČ) | D31: =IFERROR(VLOOKUP(B31,'Telefónny zoznam'!C:E, 3, FALSE), "") -> 0905 891 787 | E31: Depo Trnávka | F31: 3222 | H31: 4711 | I31: =IFERROR(VLOOKUP(H31, 'Telefónny zoznam'!C3:E2990,2, FALSE), "Name not found") -> Mazáček Peter | J31: =IFERROR(VLOOKUP(H31,'Telefónny zoznam'!C:E, 3, FALSE), "") -> 0901 796 440 | K31: Depo Trnávka | L31: 6724

Sheet Telefónny zoznam
C2: služobné číslo | D2: meno | E2: tel. číslo
C3: 242 | D3: Pajdlhauser Miroslav | E3: 0915 375 128
C4: 372 | D4: Peťko Jozef | E4: 0948 219 054
C5: 749 | D5: Orth Milan | E5: 0905 716 103
C6: 904 | D6: Garančovský Róbert | E6: 0911 677 111
C7: 986 | D7: Kmeťo Martin | E7: 0911 101 242
C8: 1162 | D8: Král Ivan | E8: 0902 326 892
C9: 1208 | D9: Žúbor Ján | E9: 0940 844 467
C10: 1226 | D10: Naď Miroslav | E10: 0903 687 235
C11: 1344 | D11: Farkaš Martin | E11: 0910 929 570
C12: 1438 | D12: Heck Vladimír | E12: 0948 688 802
C13: 2170 | D13: Hržič Mário (KPČ) | E13: 0911 644 961
C14: 2525 | D14: Šimonovič Michal KPČ | E14: 0905 750 431
... C101: 9065 | D101: Laktiš Július | E101: 0908 416 420
C102: 9076 | D102: Petrikovič Pavol | E102: 0907 698 554 | H102: 16011 | I102: =IFERROR(VLOOKUP(H102, 'Telefónny zoznam'!C3:E3000,2, FALSE), "Name not found") -> Mada Richard
C103: 9077 | D103: Bellayová Monika | E103: 0917 963 147
C104: 9108 | D104: Tučka Pavol | E104: 0918 105 044
C105: 9172 | D105: Lukáč Vladimír | E105: 0911 608 103
C106: 9174 | D106: Stríž Stano | E106: 0903 903 381
C107: 9219 | D107: Rybianská Ľudmila | E107: 0908 910 737
C108: 9230 | D108: Mojžišová Iveta | E108: 0910 241 662
C109: 9236 | D109: Gazdík Andrej | E109: 0910 456 352
C110: 9335 | D110: Sedláček Miroslav | E110: 0903 046 303
C111: 9393 | D111: Sládek Radoslav KPČ | E111: 0905 210 783
C112: 9404 | D112: Kuchta Ladislav | E112: 0903 545 353
C113: 9411 | D113: Otočka Mário | E113: 0903 742 752
C114: 9425 | D114: Hauskrecht Ľubomír | E114: 0903 418 892
... C601: 17889 | D601: Kozlík Štefan | E601: 0911 081 508
C602: 17896 | D602: Zekjiri Hasrit | E602: 0950 445 230 | H602: sl. č. | I602: meno
C603: 17904 | D603: Aidarbek uulu Baiaman | E603: 0944 359 278 | H603: 14523 | I603: =IFERROR(VLOOKUP(H603, 'Telefónny zoznam'!C3:E2010,2, FALSE), "Name not found") -> Michal Miroslav
C604: 17917 | D604: Barčák Richard | E604: 0905 802 641
C605: 17922 | D605: Schutová Monika | E605: 0918 652 898
C606: 17929 | D606: Trsťan Ivan Ing. | E606: 0903 706 111
C607: 17931 | D607: Ivor Martin | E607: 0940 057 220
C608: 17974 | D608: Pero Lukáš | E608: 0915 430 269
C609: 17984 | D609: Akybekov Ernst | E609: 0949 125 020
C610: 18003 | D610: Troian Halyna | E610: 0910 746 923
C611: 18006 | D611: Pintér Marek | E611: 0908 309 007
C612: 18008 | D612: Pajonk Vladimír | E612: 0917 304 178
C613: 18018 | D613: Šmogrovičová Petra | E613: 0917 177 753
...
